{"name": "test_call_api_with_connection_error", "status": "passed", "description": "测试连接错误", "start": 1761614695580, "stop": 1761614695581, "uuid": "20d1d3b3-08cf-414b-98c4-5c5ed8511426", "historyId": "64869a2786e0f79a1392dcd8a150d5de", "testCaseId": "fabea6391b46bce4d4d2386d3731f0f8", "fullName": "testcases.test_error_response.TestCallApi#test_call_api_with_connection_error", "labels": [{"name": "parentSuite", "value": "testcases"}, {"name": "suite", "value": "test_error_response"}, {"name": "subSuite", "value": "TestCallApi"}, {"name": "host", "value": "DESKTOP-SQEMBVG"}, {"name": "thread", "value": "15580-MainThread"}, {"name": "framework", "value": "pytest"}, {"name": "language", "value": "cpython3"}, {"name": "package", "value": "testcases.test_error_response"}]}